<?xml version="1.0" ?>
<!-- =================================================================================== -->
<!-- |    This document was autogenerated by xacro from /home/yash/ros_ws/src/multirobot_sim/master_models/urdf/ros2_bot.xacro | -->
<!-- |    EDITING THIS FILE BY HAND IS NOT RECOMMENDED                                 | -->
<!-- =================================================================================== -->
<robot name="master">
  <material name="silver">
    <color rgba="0.700 0.700 0.700 1.000"/>
  </material>
  <material name="black">
    <color rgba="0.0 0.0 0.0 1.000"/>
  </material>
  <gazebo reference="base_link">
    <material>Gazebo/DarkGrey</material>
    <mu1>0.2</mu1>
    <mu2>0.2</mu2>
    <selfCollide>true</selfCollide>
    <gravity>true</gravity>
  </gazebo>
  <gazebo reference="right_wheel_1">
    <material>Gazebo/Black</material>
    <mu1>1.0</mu1>
    <mu2>1.0</mu2>
    <selfCollide>true</selfCollide>
  </gazebo>
  <gazebo reference="left_wheel_1">
    <material>Gazebo/Black</material>
    <mu1>1.0</mu1>
    <mu2>1.0</mu2>
    <selfCollide>true</selfCollide>
  </gazebo>
  <gazebo reference="caster_1">
    <material>Gazebo/DarkGrey</material>
    <mu1>0.02</mu1>
    <mu2>0.02</mu2>
    <selfCollide>true</selfCollide>
  </gazebo>
  <!-- <gazebo reference="camera_link">
  <sensor type="camera" name="camera_sensor">
    <pose>0 0 0 0 0 0</pose>
    <visualize>true</visualize>
    <update_rate>30</update_rate>
    <camera>
      <horizontal_fov>1.047</horizontal_fov>
      <image>
        <width>640</width>
        <height>480</height>
        <format>R8G8B8</format>
      </image>
      <clip>
        <near>0.1</near>
        <far>100</far>
      </clip>
    </camera>
    <plugin name="gazebo_ros_camera_2" filename="libgazebo_ros_camera.so">
      <ros>
        <namespace></namespace>
        <remapping>image_raw:=/camera/image_raw</remapping>
      </ros>
      <frameName>camera_link</frameName>
    </plugin>
  </sensor>
</gazebo> -->
  <!-- <gazebo reference="lidar_1">
  <material>${lidar_color}</material>
  <mu1>0.2</mu1>
  <mu2>0.2</mu2>
  <selfCollide>true</selfCollide>
		<sensor name="ydlidar" type="ray">
			<always_on>true</always_on>
			<visualize>false</visualize>
			<update_rate>10</update_rate>
			<ray>
			<scan>
				<horizontal>
				<samples>720</samples>
				<resolution>1.000000</resolution>
				<min_angle>-3.14</min_angle>
				<max_angle>3.14</max_angle>
				</horizontal>
			</scan>
			<range>
				<min>0.05</min>
				<max>20.0</max>
				<resolution>0.015000</resolution>
			</range>
			<noise>
				<type>gaussian</type>
				<mean>0.0</mean>
				<stddev>0.01</stddev>
			</noise>
			</ray>
			<plugin name="scan" filename="libgazebo_ros_ray_sensor.so"> -->
  <!-- <ros>
				<remapping>~/out:=scan</remapping>
			</ros>
			<output_type>sensor_msgs/LaserScan</output_type>
			<frame_name>lidar_1</frame_name>
			</plugin>
		</sensor>
</gazebo> -->
  <!-- Differential Drive Plugin -->
  <gazebo>
    <plugin filename="libgazebo_ros_diff_drive.so" name="diff_drive_master">
      <ros>
        <!-- <namespace>/demo</namespace> -->
      </ros>
      <!-- wheels -->
      <left_joint>left_wheel_joint</left_joint>
      <right_joint>right_wheel_joint</right_joint>
      <!-- kinematics -->
      <wheel_separation>0.19</wheel_separation>
      <wheel_diameter>0.06</wheel_diameter>
      <!-- limits -->
      <max_wheel_torque>20</max_wheel_torque>
      <max_wheel_acceleration>1.0</max_wheel_acceleration>
      <!-- output -->
      <publish_odom>true</publish_odom>
      <publish_odom_tf>true</publish_odom_tf>
      <publish_wheel_tf>false</publish_wheel_tf>
      <odometry_frame>odom</odometry_frame>
      <robot_base_frame>base_link</robot_base_frame>
    </plugin>
  </gazebo>
  <!-- Laser Sensor -->
  <!-- <gazebo>
	<sensor name="ydlidar" type="ray">
		<always_on>true</always_on>
		<visualize>true</visualize>
		<update_rate>10</update_rate>
		<ray>
		<scan>
			<horizontal>
			<samples>720</samples>
			<resolution>1.000000</resolution>
			<min_angle>-3.14</min_angle>
			<max_angle>3.14</max_angle>
			</horizontal>
		</scan>
		<range>
			<min>0.05</min>
			<max>20.0</max>
			<resolution>0.015000</resolution>
		</range>
		<noise>
			<type>gaussian</type>
			<mean>0.0</mean>
			<stddev>0.01</stddev>
		</noise>
		</ray>
		<plugin name="scan_2" filename="libgazebo_ros_ray_sensor.so">
		<ros>
			<remapping>~/out:=scan_2</remapping>
		</ros>
		<output_type>sensor_msgs/LaserScan</output_type>
		<frame_name>lidar_1</frame_name>
		</plugin>
	</sensor>
</gazebo> -->
  <link name="base_link">
    <inertial>
      <origin rpy="0 0 0" xyz="0.0026283699322052346 1.1577803157919558e-17 0.03202679041651883"/>
      <mass value="0.8326833430570596"/>
      <inertia ixx="0.001511" ixy="0.0" ixz="-1.3e-05" iyy="0.002413" iyz="0.0" izz="0.003751"/>
    </inertial>
    <visual>
      <origin rpy="0 0 0" xyz="0 0 0"/>
      <geometry>
        <mesh filename="file:///home/yash/ros_ws/install/multirobot_sim/share/multirobot_sim/master_models/meshes/base_link.stl" scale="0.001 0.001 0.001"/>
      </geometry>
      <material name="silver"/>
    </visual>
    <collision>
      <origin rpy="0 0 0" xyz="0 0 0"/>
      <geometry>
        <mesh filename="file:///home/yash/ros_ws/install/multirobot_sim/share/multirobot_sim/master_models/meshes/base_link.stl" scale="0.001 0.001 0.001"/>
      </geometry>
    </collision>
  </link>
  <link name="right_wheel_1">
    <inertial>
      <origin rpy="0 0 0" xyz="4.829470157119431e-15 -0.012500000000000011 1.419697692739419e-14"/>
      <mass value="0.008246680715673199"/>
      <inertia ixx="2e-06" ixy="-0.0" ixz="0.0" iyy="4e-06" iyz="-0.0" izz="2e-06"/>
    </inertial>
    <visual>
      <origin rpy="0 0 0" xyz="0.065 0.085 -0.03"/>
      <geometry>
        <mesh filename="file:///home/yash/ros_ws/install/multirobot_sim/share/multirobot_sim/master_models/meshes/right_wheel_1.stl" scale="0.001 0.001 0.001"/>
      </geometry>
      <material name="black"/>
    </visual>
    <collision>
      <origin rpy="0 0 0" xyz="0.065 0.085 -0.03"/>
      <geometry>
        <mesh filename="file:///home/yash/ros_ws/install/multirobot_sim/share/multirobot_sim/master_models/meshes/right_wheel_1.stl" scale="0.001 0.001 0.001"/>
      </geometry>
    </collision>
  </link>
  <link name="left_wheel_1">
    <inertial>
      <origin rpy="0 0 0" xyz="-1.3711254354120683e-14 0.012499999999999997 5.5198901005582e-15"/>
      <mass value="0.008246680715673199"/>
      <inertia ixx="2e-06" ixy="-0.0" ixz="-0.0" iyy="4e-06" iyz="0.0" izz="2e-06"/>
    </inertial>
    <visual>
      <origin rpy="0 0 0" xyz="0.065 -0.085 -0.03"/>
      <geometry>
        <mesh filename="file:///home/yash/ros_ws/install/multirobot_sim/share/multirobot_sim/master_models/meshes/left_wheel_1.stl" scale="0.001 0.001 0.001"/>
      </geometry>
      <material name="black"/>
    </visual>
    <collision>
      <origin rpy="0 0 0" xyz="0.065 -0.085 -0.03"/>
      <geometry>
        <mesh filename="file:///home/yash/ros_ws/install/multirobot_sim/share/multirobot_sim/master_models/meshes/left_wheel_1.stl" scale="0.001 0.001 0.001"/>
      </geometry>
    </collision>
  </link>
  <link name="caster_1">
    <inertial>
      <origin rpy="0 0 0" xyz="-0.03 -9.860761315262648e-34 -0.006750000000000004"/>
      <mass value="0.06936047530503713"/>
      <inertia ixx="5e-06" ixy="-0.0" ixz="0.0" iyy="5e-06" iyz="0.0" izz="7e-06"/>
    </inertial>
    <visual>
      <origin rpy="0 0 0" xyz="-0.1 -0.0 -0.0175"/>
      <geometry>
        <mesh filename="file:///home/yash/ros_ws/install/multirobot_sim/share/multirobot_sim/master_models/meshes/caster_1.stl" scale="0.001 0.001 0.001"/>
      </geometry>
      <material name="silver"/>
    </visual>
    <collision>
      <origin rpy="0 0 0" xyz="-0.1 -0.0 -0.0175"/>
      <geometry>
        <mesh filename="file:///home/yash/ros_ws/install/multirobot_sim/share/multirobot_sim/master_models/meshes/caster_1.stl" scale="0.001 0.001 0.001"/>
      </geometry>
    </collision>
  </link>
  <link name="lidar_1">
    <inertial>
      <origin rpy="0 0 0" xyz="5.026061718855929e-18 0.0 0.0049999999999999906"/>
      <mass value="0.2219535209761188"/>
      <inertia ixx="5.2e-05" ixy="0.0" ixz="-0.0" iyy="5.2e-05" iyz="-0.0" izz="0.0001"/>
    </inertial>
    <visual>
      <origin rpy="0 0 0" xyz="-0.0 -0.0 -0.0675"/>
      <geometry>
        <mesh filename="file:///home/yash/ros_ws/install/multirobot_sim/share/multirobot_sim/master_models/meshes/lidar_1.stl" scale="0.001 0.001 0.001"/>
      </geometry>
      <material name="silver"/>
    </visual>
    <collision>
      <origin rpy="0 0 0" xyz="-0.0 -0.0 -0.0675"/>
      <geometry>
        <mesh filename="file:///home/yash/ros_ws/install/multirobot_sim/share/multirobot_sim/master_models/meshes/lidar_1.stl" scale="0.001 0.001 0.001"/>
      </geometry>
    </collision>
  </link>
  <!-- Camera Link
<link name="camera_link">
  <inertial>
    <origin xyz="0 0 0" rpy="0 0 0"/>
    <mass value="0.01"/>
    <inertia ixx="1e-5" iyy="1e-5" izz="1e-5" ixy="0.0" iyz="0.0" ixz="0.0"/>
  </inertial>
  <visual>
    <origin xyz="0.0 0.0 0.1" rpy="0 0 0"/>
    <geometry>
      <box size="0.05 0.05 0.05"/>
    </geometry>
    <material name="black"/>
  </visual>
  <collision>
    <origin xyz="0.0 0.0 0.1" rpy="0 0 0"/>
    <geometry>
      <box size="0.05 0.05 0.05"/>
    </geometry>
  </collision>
</link>

Camera Joint
<joint name="camera_joint" type="fixed">
  <origin xyz="0.0 0.0 0.1" rpy="0 0 0"/>
  <parent link="base_link"/>
  <child link="camera_link"/>
</joint> -->
  <joint name="right_wheel_joint" type="continuous">
    <origin rpy="0 0 0" xyz="-0.065 -0.085 0.03"/>
    <parent link="base_link"/>
    <child link="right_wheel_1"/>
    <axis xyz="0.0 1.0 0.0"/>
  </joint>
  <joint name="left_wheel_joint" type="continuous">
    <origin rpy="0 0 0" xyz="-0.065 0.085 0.03"/>
    <parent link="base_link"/>
    <child link="left_wheel_1"/>
    <axis xyz="0.0 1.0 0.0"/>
  </joint>
  <joint name="caster_joint" type="fixed">
    <origin rpy="0 0 0" xyz="0.1 0.0 0.0175"/>
    <parent link="base_link"/>
    <child link="caster_1"/>
  </joint>
  <joint name="lidar_joint" type="fixed">
    <origin rpy="0 0 0" xyz="0.0 0.0 0.0675"/>
    <parent link="base_link"/>
    <child link="lidar_1"/>
  </joint>
</robot>
