<?xml version="1.0" ?>
<!-- =================================================================================== -->
<!-- |    This document was autogenerated by xacro from /home/yash/ros_ws/src/multirobot_sim/slave_models/urdf/tortoisebot.xacro | -->
<!-- |    EDITING THIS FILE BY HAND IS NOT RECOMMENDED                                 | -->
<!-- =================================================================================== -->
<robot name="slave">
  <material name="grey">
    <color rgba="0.300 0.300 0.300 1.000"/>
  </material>
  <material name="black">
    <color rgba="0.000 0.000 0.000 1.000"/>
  </material>
  <material name="blue">
    <color rgba="0.000 0.000 1.000 1.000"/>
  </material>
  <!--  ##########  BODY COLOR  ##########  -->
  <gazebo reference="base_link">
    <material>Gazebo/DarkGrey</material>
  </gazebo>
  <gazebo reference="imu">
    <material>Gazebo/DarkGrey</material>
  </gazebo>
  <gazebo reference="camera">
    <material>Gazebo/DarkGrey</material>
  </gazebo>
  <!--  ##########  WHEEL COLOR  ##########  -->
  <gazebo reference="wheel_right">
    <material>Gazebo/Black</material>
  </gazebo>
  <gazebo reference="wheel_left">
    <material>Gazebo/Black</material>
  </gazebo>
  <!--  ##########  CASTER COLOR  ##########  -->
  <gazebo reference="caster">
    <material>Gazebo/Grey</material>
  </gazebo>
  <!--  ##########  LIDAR COLOR  ##########  -->
  <gazebo reference="lidar_body">
    <material>Gazebo/Black</material>
  </gazebo>
  <gazebo reference="lidar_motorend">
    <material>Gazebo/Blue</material>
  </gazebo>
  <gazebo reference="lidar_bottom">
    <material>Gazebo/Blue</material>
  </gazebo>
  <gazebo reference="lidar">
    <material>Gazebo/Blue</material>
  </gazebo>
  <!--  ##########  WHEEL FRICTION  ##########  -->
  <gazebo reference="wheel_right">
    <mu1>1000.0</mu1>
    <mu2>1000.0</mu2>
    <selfCollide>true</selfCollide>
  </gazebo>
  <gazebo reference="wheel_left">
    <mu1>1000.0</mu1>
    <mu2>1000.0</mu2>
    <selfCollide>true</selfCollide>
  </gazebo>
  <!--  ##########  CASTER FRICTION  ##########  -->
  <gazebo reference="caster">
    <mu1>0.1</mu1>
    <mu2>0.1</mu2>
    <selfCollide>true</selfCollide>
  </gazebo>
  <!--  ##########  STANDARD FRICTION  ##########  -->
  <gazebo reference="base_link">
    <mu1>100.0</mu1>
    <mu2>100.0</mu2>
    <selfCollide>true</selfCollide>
    <gravity>true</gravity>
  </gazebo>
  <gazebo reference="lidar_body">
    <mu1>100.0</mu1>
    <mu2>100.0</mu2>
    <selfCollide>true</selfCollide>
  </gazebo>
  <gazebo reference="lidar_motorend">
    <mu1>100.0</mu1>
    <mu2>100.0</mu2>
    <selfCollide>true</selfCollide>
  </gazebo>
  <gazebo reference="lidar_bottom">
    <mu1>100.0</mu1>
    <mu2>100.0</mu2>
    <selfCollide>true</selfCollide>
  </gazebo>
  <gazebo reference="lidar">
    <mu1>100.0</mu1>
    <mu2>100.0</mu2>
    <selfCollide>true</selfCollide>
  </gazebo>
  <gazebo reference="imu">
    <mu1>100.0</mu1>
    <mu2>100.0</mu2>
    <selfCollide>true</selfCollide>
  </gazebo>
  <gazebo reference="camera">
    <mu1>100.0</mu1>
    <mu2>100.0</mu2>
    <selfCollide>true</selfCollide>
  </gazebo>
  <!-- Differential drive plugin for gazebo -->
  <gazebo>
    <plugin filename="libgazebo_ros_diff_drive.so" name="diff_drive_slave">
      <ros>
        <!-- <namespace>/demo</namespace> -->
      </ros>
      <!-- wheels -->
      <left_joint>motor_left</left_joint>
      <right_joint>motor_right</right_joint>
      <!-- kinematics -->
      <wheel_separation>0.17186</wheel_separation>
      <wheel_diameter>0.065</wheel_diameter>
      <!-- limits -->
      <max_wheel_torque>20</max_wheel_torque>
      <max_wheel_acceleration>1.0</max_wheel_acceleration>
      <!-- output -->
      <publish_odom>true</publish_odom>
      <publish_odom_tf>true</publish_odom_tf>
      <publish_wheel_tf>false</publish_wheel_tf>
      <odometry_frame>odom</odometry_frame>
      <robot_base_frame>base_link</robot_base_frame>
    </plugin>
  </gazebo>
  <!--  ##########  LIDAR PLUGIN  ##########  -->
  <gazebo reference="lidar">
    <sensor name="ydlidar" type="ray">
      <always_on>true</always_on>
      <visualize>false</visualize>
      <update_rate>10</update_rate>
      <ray>
        <scan>
          <horizontal>
            <samples>720</samples>
            <resolution>1.000000</resolution>
            <min_angle>-3.14</min_angle>
            <max_angle>3.14</max_angle>
          </horizontal>
        </scan>
        <range>
          <min>0.05</min>
          <max>20.0</max>
          <resolution>0.015000</resolution>
        </range>
        <noise>
          <type>gaussian</type>
          <mean>0.0</mean>
          <stddev>0.01</stddev>
        </noise>
      </ray>
      <plugin filename="libgazebo_ros_ray_sensor.so" name="scan">
        <ros>
          <remapping>~/out:=scan</remapping>
        </ros>
        <output_type>sensor_msgs/LaserScan</output_type>
        <frame_name>lidar</frame_name>
      </plugin>
    </sensor>
  </gazebo>
  <!--  ##########  CAMERA PLUGIN  ##########  -->
  <gazebo reference="camera">
    <sensor name="camera" type="camera">
      <update_rate>30.0</update_rate>
      <camera name="head">
        <horizontal_fov>1.3962634</horizontal_fov>
        <image>
          <width>800</width>
          <height>800</height>
          <format>R8G8B8</format>
        </image>
        <clip>
          <near>0.02</near>
          <far>300</far>
        </clip>
        <noise>
          <type>gaussian</type>
          <!-- Noise is sampled independently per pixel on each frame.
               That pixel's noise value is added to each of its color
               channels, which at that point lie in the range [0,1]. -->
          <mean>0.0</mean>
          <stddev>0.007</stddev>
        </noise>
      </camera>
      <plugin filename="libgazebo_ros_camera.so" name="camera_controller">
        <alwaysOn>true</alwaysOn>
        <updateRate>0.0</updateRate>
        <cameraName>camera</cameraName>
        <imageTopicName>image_raw</imageTopicName>
        <cameraInfoTopicName>camera_info</cameraInfoTopicName>
        <frameName>camera</frameName>
        <hackBaseline>0.07</hackBaseline>
        <distortionK1>0.0</distortionK1>
        <distortionK2>0.0</distortionK2>
        <distortionK3>0.0</distortionK3>
        <distortionT1>0.0</distortionT1>
        <distortionT2>0.0</distortionT2>
      </plugin>
    </sensor>
  </gazebo>
  <link name="base_link">
    <inertial>
      <origin rpy="0 0 0" xyz="-0.002760040106013823 -0.001188341092731165 0.0718803300182357"/>
      <mass value="0.5998126574179536"/>
      <inertia ixx="0.001977" ixy="-1.9e-05" ixz="1.6e-05" iyy="0.001845" iyz="3.1e-05" izz="0.001587"/>
    </inertial>
    <visual>
      <origin rpy="0 0 0" xyz="0 0 0"/>
      <geometry>
        <mesh filename="file:///home/yash/ros_ws/install/multirobot_sim/share/multirobot_sim/slave_models/meshes/base_link.stl" scale="0.001 0.001 0.001"/>
      </geometry>
      <material name="grey"/>
    </visual>
    <collision>
      <origin rpy="0 0 0" xyz="0 0 0"/>
      <geometry>
        <mesh filename="file:///home/yash/ros_ws/install/multirobot_sim/share/multirobot_sim/slave_models/meshes/base_link.stl" scale="0.001 0.001 0.001"/>
      </geometry>
    </collision>
  </link>
  <link name="wheel_right">
    <inertial>
      <origin rpy="0 0 0" xyz="-1.3588436534317516e-07 -0.01588997385974819 2.4327475205837557e-07"/>
      <mass value="0.23341302374485867"/>
      <inertia ixx="9.6e-05" ixy="-0.0" ixz="0.0" iyy="0.00016" iyz="0.0" izz="9.6e-05"/>
    </inertial>
    <visual>
      <origin rpy="0 0 0" xyz="-0.0325 0.07073 -0.03245"/>
      <geometry>
        <mesh filename="file:///home/yash/ros_ws/install/multirobot_sim/share/multirobot_sim/slave_models/meshes/wheel_right.stl" scale="0.001 0.001 0.001"/>
      </geometry>
      <material name="black"/>
    </visual>
    <collision>
      <origin rpy="0 0 0" xyz="-0.0325 0.07073 -0.03245"/>
      <geometry>
        <mesh filename="file:///home/yash/ros_ws/install/multirobot_sim/share/multirobot_sim/slave_models/meshes/wheel_right.stl" scale="0.001 0.001 0.001"/>
      </geometry>
    </collision>
  </link>
  <link name="wheel_left">
    <inertial>
      <origin rpy="0 0 0" xyz="-1.3200802984753013e-07 0.015889975585968247 2.563618809944823e-07"/>
      <mass value="0.2334125809795772"/>
      <inertia ixx="9.6e-05" ixy="0.0" ixz="0.0" iyy="0.00016" iyz="-0.0" izz="9.6e-05"/>
    </inertial>
    <visual>
      <origin rpy="0 0 0" xyz="-0.0325 -0.07073 -0.03245"/>
      <geometry>
        <mesh filename="file:///home/yash/ros_ws/install/multirobot_sim/share/multirobot_sim/slave_models/meshes/wheel_left.stl" scale="0.001 0.001 0.001"/>
      </geometry>
      <material name="black"/>
    </visual>
    <collision>
      <origin rpy="0 0 0" xyz="-0.0325 -0.07073 -0.03245"/>
      <geometry>
        <mesh filename="file:///home/yash/ros_ws/install/multirobot_sim/share/multirobot_sim/slave_models/meshes/wheel_left.stl" scale="0.001 0.001 0.001"/>
      </geometry>
    </collision>
  </link>
  <link name="caster">
    <inertial>
      <origin rpy="0 0 0" xyz="-0.01100000059604822 -1.4270326137978878e-17 -0.006845279720279717"/>
      <mass value="0.02931481955170001"/>
      <inertia ixx="2e-06" ixy="-0.0" ixz="0.0" iyy="2e-06" iyz="-0.0" izz="1e-06"/>
    </inertial>
    <visual>
      <origin rpy="0 0 0" xyz="0.032 -0.0 -0.01915"/>
      <geometry>
        <mesh filename="file:///home/yash/ros_ws/install/multirobot_sim/share/multirobot_sim/slave_models/meshes/caster.stl" scale="0.001 0.001 0.001"/>
      </geometry>
      <material name="black"/>
    </visual>
    <collision>
      <origin rpy="0 0 0" xyz="0.032 -0.0 -0.01915"/>
      <geometry>
        <mesh filename="file:///home/yash/ros_ws/install/multirobot_sim/share/multirobot_sim/slave_models/meshes/caster.stl" scale="0.001 0.001 0.001"/>
      </geometry>
    </collision>
  </link>
  <link name="lidar_body">
    <inertial>
      <origin rpy="0 0 0" xyz="0.04189252309401799 -0.030999999999999896 0.02544713291508699"/>
      <mass value="0.07136843474102665"/>
      <inertia ixx="2.3e-05" ixy="0.0" ixz="5e-06" iyy="6.1e-05" iyz="0.0" izz="7.7e-05"/>
    </inertial>
    <visual>
      <origin rpy="0 0 0" xyz="0.022 -0.031 -0.14715"/>
      <geometry>
        <mesh filename="file:///home/yash/ros_ws/install/multirobot_sim/share/multirobot_sim/slave_models/meshes/lidar_body.stl" scale="0.001 0.001 0.001"/>
      </geometry>
      <material name="black"/>
    </visual>
    <collision>
      <origin rpy="0 0 0" xyz="0.022 -0.031 -0.14715"/>
      <geometry>
        <mesh filename="file:///home/yash/ros_ws/install/multirobot_sim/share/multirobot_sim/slave_models/meshes/lidar_body.stl" scale="0.001 0.001 0.001"/>
      </geometry>
    </collision>
  </link>
  <link name="lidar_motorend">
    <inertial>
      <origin rpy="0 0 0" xyz="-1.3877787807814457e-17 7.710435591426653e-18 0.002750000000000058"/>
      <mass value="0.0005131791599638964"/>
      <inertia ixx="0.0" ixy="-0.0" ixz="0.0" iyy="0.0" iyz="0.0" izz="0.0"/>
    </inertial>
    <visual>
      <origin rpy="0 0 0" xyz="-0.05 -0.0 -0.18065"/>
      <geometry>
        <mesh filename="file:///home/yash/ros_ws/install/multirobot_sim/share/multirobot_sim/slave_models/meshes/lidar_motorend.stl" scale="0.001 0.001 0.001"/>
      </geometry>
      <material name="blue"/>
    </visual>
    <collision>
      <origin rpy="0 0 0" xyz="-0.05 -0.0 -0.18065"/>
      <geometry>
        <mesh filename="file:///home/yash/ros_ws/install/multirobot_sim/share/multirobot_sim/slave_models/meshes/lidar_motorend.stl" scale="0.001 0.001 0.001"/>
      </geometry>
    </collision>
  </link>
  <link name="lidar_bottom">
    <inertial>
      <origin rpy="0 0 0" xyz="-1.0850529511452296e-17 5.425264755726148e-18 0.007750000000000035"/>
      <mass value="0.062236577058626265"/>
      <inertia ixx="1.8e-05" ixy="-0.0" ixz="-0.0" iyy="1.8e-05" iyz="0.0" izz="3.3e-05"/>
    </inertial>
    <visual>
      <origin rpy="0 0 0" xyz="0.0 -0.0 -0.18065"/>
      <geometry>
        <mesh filename="file:///home/yash/ros_ws/install/multirobot_sim/share/multirobot_sim/slave_models/meshes/lidar_bottom.stl" scale="0.001 0.001 0.001"/>
      </geometry>
      <material name="blue"/>
    </visual>
    <collision>
      <origin rpy="0 0 0" xyz="0.0 -0.0 -0.18065"/>
      <geometry>
        <mesh filename="file:///home/yash/ros_ws/install/multirobot_sim/share/multirobot_sim/slave_models/meshes/lidar_bottom.stl" scale="0.001 0.001 0.001"/>
      </geometry>
    </collision>
  </link>
  <link name="lidar">
    <inertial>
      <origin rpy="0 0 0" xyz="-1.2613740557063325e-17 4.204580185687775e-18 0.00500000000000006"/>
      <mass value="0.040152630360403944"/>
      <inertia ixx="1.1e-05" ixy="0.0" ixz="0.0" iyy="1.1e-05" iyz="-0.0" izz="2.2e-05"/>
    </inertial>
    <visual>
      <origin rpy="0 0 0" xyz="0.0 -0.0 -0.19615"/>
      <geometry>
        <mesh filename="file:///home/yash/ros_ws/install/multirobot_sim/share/multirobot_sim/slave_models/meshes/lidar_top.stl" scale="0.001 0.001 0.001"/>
      </geometry>
      <material name="blue"/>
    </visual>
    <collision>
      <origin rpy="0 0 0" xyz="0.0 -0.0 -0.19615"/>
      <geometry>
        <mesh filename="file:///home/yash/ros_ws/install/multirobot_sim/share/multirobot_sim/slave_models/meshes/lidar_top.stl" scale="0.001 0.001 0.001"/>
      </geometry>
    </collision>
  </link>
  <link name="imu">
    <inertial>
      <origin rpy="0 0 0" xyz="-0.005006317892412869 0.010331821776814253 0.0005641458401822869"/>
      <mass value="0.0005786974233911084"/>
      <inertia ixx="0.0" ixy="0.0" ixz="-0.0" iyy="0.0" iyz="-0.0" izz="0.0"/>
    </inertial>
    <visual>
      <origin rpy="0 0 0" xyz="-0.04 0.01025 -0.10543"/>
      <geometry>
        <mesh filename="file:///home/yash/ros_ws/install/multirobot_sim/share/multirobot_sim/slave_models/meshes/imu.stl" scale="0.001 0.001 0.001"/>
      </geometry>
      <material name="grey"/>
    </visual>
    <collision>
      <origin rpy="0 0 0" xyz="-0.04 0.01025 -0.10543"/>
      <geometry>
        <mesh filename="file:///home/yash/ros_ws/install/multirobot_sim/share/multirobot_sim/slave_models/meshes/imu.stl" scale="0.001 0.001 0.001"/>
      </geometry>
    </collision>
  </link>
  <link name="camera">
    <inertial>
      <origin rpy="0 0 0" xyz="-0.000736316919000779 9.521361965188852e-15 0.01215919671545948"/>
      <mass value="0.011070080401829364"/>
      <inertia ixx="1e-06" ixy="-0.0" ixz="0.0" iyy="1e-06" iyz="0.0" izz="1e-06"/>
    </inertial>
    <visual>
      <origin rpy="0 0 0" xyz="-0.061 -0.0 -0.11515"/>
      <geometry>
        <mesh filename="file:///home/yash/ros_ws/install/multirobot_sim/share/multirobot_sim/slave_models/meshes/camera.stl" scale="0.001 0.001 0.001"/>
      </geometry>
      <material name="grey"/>
    </visual>
    <collision>
      <origin rpy="0 0 0" xyz="-0.061 -0.0 -0.11515"/>
      <geometry>
        <mesh filename="file:///home/yash/ros_ws/install/multirobot_sim/share/multirobot_sim/slave_models/meshes/camera.stl" scale="0.001 0.001 0.001"/>
      </geometry>
    </collision>
  </link>
  <joint name="motor_right" type="continuous">
    <origin rpy="0 0 0" xyz="0.0325 -0.07073 0.03245"/>
    <parent link="base_link"/>
    <child link="wheel_right"/>
    <axis xyz="0 1 0"/>
  </joint>
  <joint name="motor_left" type="continuous">
    <origin rpy="0 0 0" xyz="0.0325 0.07073 0.03245"/>
    <parent link="base_link"/>
    <child link="wheel_left"/>
    <axis xyz="0 1 0"/>
  </joint>
  <joint name="Rigid3" type="fixed">
    <origin rpy="0 0 0" xyz="-0.032 0.0 0.01915"/>
    <parent link="base_link"/>
    <child link="caster"/>
  </joint>
  <joint name="Rigid4" type="fixed">
    <origin rpy="0 0 0" xyz="-0.022 0.031 0.14715"/>
    <parent link="base_link"/>
    <child link="lidar_body"/>
  </joint>
  <joint name="Rigid5" type="fixed">
    <origin rpy="0 0 0" xyz="0.072 -0.031 0.0335"/>
    <parent link="lidar_body"/>
    <child link="lidar_motorend"/>
  </joint>
  <joint name="Rigid6" type="fixed">
    <origin rpy="0 0 0" xyz="0.022 -0.031 0.0335"/>
    <parent link="lidar_body"/>
    <child link="lidar_bottom"/>
  </joint>
  <joint name="Rigid7" type="fixed">
    <origin rpy="0 0 0" xyz="0.0 0.0 0.0155"/>
    <parent link="lidar_bottom"/>
    <child link="lidar"/>
  </joint>
  <joint name="Rigid8" type="fixed">
    <origin rpy="0 0 0" xyz="0.04 -0.01025 0.10543"/>
    <parent link="base_link"/>
    <child link="imu"/>
  </joint>
  <joint name="Rigid9" type="fixed">
    <origin rpy="0 0 0" xyz="0.061 0.0 0.11515"/>
    <parent link="base_link"/>
    <child link="camera"/>
  </joint>
</robot>
